<?xml version="1.0" ?>
<robot name="hand">
  <link name="world"/>
  <joint name="world_joint" type="fixed">
    <origin xyz="0.0 0.0 0.0"/>
    <parent link="world"/>
    <child link="link_0"/>
  </joint>
  <joint name="right_inner_joint_0" type="revolute">
    <origin xyz="0.003782460931688547 0.0 0.1288294792175293"/>
    <parent link="link_0"/>
    <child link="link_1"/>
    <axis xyz="0.0 1.0 0.0"/>
    <limit lower="-0.059999995" upper="1.2294571" effort="1000.0" velocity="2.0"/>
  </joint>
  <joint name="right_tip_joint_0" type="revolute">
    <origin xyz="-0.001226305030286312 0.0 0.08589763753116131"/>
    <parent link="link_1"/>
    <child link="link_2"/>
    <axis xyz="0.0 -1.0 0.0"/>
    <limit lower="-0.060000002" upper="1.2294569" effort="1000.0" velocity="2.0"/>
  </joint>
  <link name="link_2">
    <visual>
      <geometry>
        <mesh filename="assets/geom_5.obj"/>
      </geometry>
      <origin xyz="0.00462533812969923 0.0 0.01904049701988697"/>
    </visual>
    <collision>
      <geometry>
        <mesh filename="assets/geom_5_col0.obj"/>
      </geometry>
      <origin xyz="0.00462533812969923 0.0 0.01904049701988697"/>
    </collision>
  </link>
  <link name="link_1">
    <visual>
      <geometry>
        <mesh filename="assets/geom_2.obj"/>
      </geometry>
      <origin xyz="0.0023443857207894325 0.0 0.04426409304141998"/>
    </visual>
    <collision>
      <geometry>
        <mesh filename="assets/geom_2_col0.obj"/>
      </geometry>
      <origin xyz="0.0023443857207894325 0.0 0.04426409304141998"/>
    </collision>
    <visual>
      <geometry>
        <mesh filename="assets/geom_3.obj"/>
      </geometry>
      <origin xyz="0.00705016078427434 0.0 0.006694108247756958"/>
    </visual>
    <collision>
      <geometry>
        <mesh filename="assets/geom_3_col0.obj"/>
      </geometry>
      <origin xyz="0.00705016078427434 0.0 0.006694108247756958"/>
    </collision>
    <visual>
      <geometry>
        <mesh filename="assets/geom_4.obj"/>
      </geometry>
      <origin xyz="0.006050162250176072 0.0 0.04982762783765793"/>
    </visual>
    <collision>
      <geometry>
        <mesh filename="assets/geom_4_col0.obj"/>
      </geometry>
      <origin xyz="0.006050162250176072 0.0 0.04982762783765793"/>
    </collision>
  </link>
  <joint name="left_inner_joint_0" type="revolute">
    <origin xyz="-0.003782454412430525 -4.400499165058136e-08 0.1288294792175293"/>
    <parent link="link_0"/>
    <child link="link_3"/>
    <axis xyz="0.0 -1.0 0.0"/>
    <limit lower="-0.059999995" upper="1.2294571" effort="1000.0" velocity="2.0"/>
  </joint>
  <joint name="left_tip_joint_0" type="revolute">
    <origin xyz="0.0012263043317943811 1.885928213596344e-08 0.08589763753116131"/>
    <parent link="link_3"/>
    <child link="link_4"/>
    <axis xyz="0.0 1.0 0.0"/>
    <limit lower="-0.060000002" upper="1.2294569" effort="1000.0" velocity="2.0"/>
  </joint>
  <link name="link_4">
    <visual>
      <geometry>
        <mesh filename="assets/geom_9.obj"/>
      </geometry>
      <origin xyz="-0.00462533812969923 0.0 0.01904049701988697"/>
    </visual>
    <collision>
      <geometry>
        <mesh filename="assets/geom_9_col0.obj"/>
      </geometry>
      <origin xyz="-0.00462533812969923 0.0 0.01904049701988697"/>
    </collision>
  </link>
  <link name="link_3">
    <visual>
      <geometry>
        <mesh filename="assets/geom_6.obj"/>
      </geometry>
      <origin xyz="-0.0023443917743861675 0.0 0.04426409304141998"/>
    </visual>
    <collision>
      <geometry>
        <mesh filename="assets/geom_6_col0.obj"/>
      </geometry>
      <origin xyz="-0.0023443917743861675 0.0 0.04426409304141998"/>
    </collision>
    <visual>
      <geometry>
        <mesh filename="assets/geom_7.obj"/>
      </geometry>
      <origin xyz="-0.007050167070701718 -3.4226104617118835e-08 0.006694108247756958"/>
    </visual>
    <collision>
      <geometry>
        <mesh filename="assets/geom_7_col0.obj"/>
      </geometry>
      <origin xyz="-0.007050167070701718 -3.4226104617118835e-08 0.006694108247756958"/>
    </collision>
    <visual>
      <geometry>
        <mesh filename="assets/geom_8.obj"/>
      </geometry>
      <origin xyz="-0.006050167605280876 -2.7241185307502747e-08 0.04982762783765793"/>
    </visual>
    <collision>
      <geometry>
        <mesh filename="assets/geom_8_col0.obj"/>
      </geometry>
      <origin xyz="-0.006050167605280876 -2.7241185307502747e-08 0.04982762783765793"/>
    </collision>
  </link>
  <link name="link_0">
    <visual>
      <geometry>
        <mesh filename="assets/geom_0.obj"/>
      </geometry>
      <origin xyz="0.0 0.0 0.020664164796471596"/>
    </visual>
    <collision>
      <geometry>
        <mesh filename="assets/geom_0_col0.obj"/>
      </geometry>
      <origin xyz="0.0 0.0 0.020664164796471596"/>
    </collision>
    <visual>
      <geometry>
        <mesh filename="assets/geom_1.obj"/>
      </geometry>
      <origin xyz="0.0 4.656612873077393e-10 0.09046056866645813"/>
    </visual>
    <collision>
      <geometry>
        <mesh filename="assets/geom_1_col0.obj"/>
      </geometry>
      <origin xyz="0.0 4.656612873077393e-10 0.09046056866645813"/>
    </collision>
  </link>
</robot>