<?xml version="1.0" ?>
<robot name="hand">
  <link name="hand_x_link"/>
  <link name="hand_y_link"/>
  <link name="hand_z_link"/>
  <link name="hand_spherical_link"/>
  <joint name="hand_x_joint" type="prismatic">
    <origin rpy="0 0 0" xyz="0 0 0"/>
    <parent link="hand_x_link"/>
    <child link="hand_y_link"/>
    <axis xyz="1 0 0"/>
    <dynamics damping="10.0"/>
    <limit lower="-100.0" upper="100.0" effort="200.0" velocity="1.0"/>
  </joint>
  <joint name="hand_y_joint" type="prismatic">
    <origin rpy="0 0 0" xyz="0 0 0"/>
    <parent link="hand_y_link"/>
    <child link="hand_z_link"/>
    <axis xyz="0 1 0"/>
    <dynamics damping="10.0"/>
    <limit lower="-100.0" upper="100.0" effort="200.0" velocity="1.0"/>
  </joint>
  <joint name="hand_z_joint" type="prismatic">
    <origin rpy="0 0 0" xyz="0 0 0"/>
    <parent link="hand_z_link"/>
    <child link="hand_spherical_link"/>
    <axis xyz="0 0 1"/>
    <dynamics damping="10.0"/>
    <limit lower="-100.0" upper="100.0" effort="200.0" velocity="1.0"/>
  </joint>
  <joint name="spherical_joint" type="spherical">
    <origin rpy="0 0 0" xyz="0 0 0"/>
    <parent link="hand_spherical_link"/>
    <child link="world"/>
    <limit lower="-4.0" upper="4.0" effort="1000.0" velocity="100.0"/>
  </joint>
  <link name="world"/>
  <joint name="world_joint" type="fixed">
    <origin xyz="0.0 0.0 0.0"/>
    <parent link="world"/>
    <child link="link_0"/>
  </joint>
  <joint name="right_inner_joint_0" type="revolute">
    <origin xyz="0.010454459581524134 0.0 0.11163341999053955"/>
    <parent link="link_0"/>
    <child link="link_1"/>
    <axis xyz="0.0 1.0 0.0"/>
    <limit lower="-0.059999995" upper="0.8503265" effort="1000.0" velocity="2.0"/>
  </joint>
  <joint name="right_tip_joint_0" type="revolute">
    <origin xyz="-0.008023430360481143 0.0 0.08564414083957672"/>
    <parent link="link_1"/>
    <child link="link_2"/>
    <axis xyz="0.0 -1.0 0.0"/>
    <limit lower="-0.060000002" upper="0.8503265" effort="1000.0" velocity="2.0"/>
  </joint>
  <link name="link_2">
    <visual>
      <geometry>
        <mesh filename="assets/geom_5.obj"/>
      </geometry>
      <origin xyz="0.002854451769962907 0.0 0.019342653453350067"/>
    </visual>
    <collision>
      <geometry>
        <mesh filename="assets/geom_5_col0.obj"/>
      </geometry>
      <origin xyz="0.002854451769962907 0.0 0.019342653453350067"/>
    </collision>
  </link>
  <link name="link_1">
    <visual>
      <geometry>
        <mesh filename="assets/geom_2.obj"/>
      </geometry>
      <origin xyz="-0.004465968813747168 0.0 0.04432525485754013"/>
    </visual>
    <collision>
      <geometry>
        <mesh filename="assets/geom_2_col0.obj"/>
      </geometry>
      <origin xyz="-0.004465968813747168 0.0 0.04432525485754013"/>
    </collision>
    <visual>
      <geometry>
        <mesh filename="assets/geom_3.obj"/>
      </geometry>
      <origin xyz="0.007051356602460146 0.0 0.009746059775352478"/>
    </visual>
    <collision>
      <geometry>
        <mesh filename="assets/geom_3_col0.obj"/>
      </geometry>
      <origin xyz="0.007051356602460146 0.0 0.009746059775352478"/>
    </collision>
    <visual>
      <geometry>
        <mesh filename="assets/geom_4.obj"/>
      </geometry>
      <origin xyz="0.006051356205716729 0.0 0.05256493389606476"/>
    </visual>
    <collision>
      <geometry>
        <mesh filename="assets/geom_4_col0.obj"/>
      </geometry>
      <origin xyz="0.006051356205716729 0.0 0.05256493389606476"/>
    </collision>
  </link>
  <joint name="left_inner_joint_0" type="revolute">
    <origin xyz="-0.010454458184540272 -4.307366907596588e-08 0.11163341999053955"/>
    <parent link="link_0"/>
    <child link="link_3"/>
    <axis xyz="0.0 -1.0 0.0"/>
    <limit lower="-0.059999995" upper="0.8503265" effort="1000.0" velocity="2.0"/>
  </joint>
  <joint name="left_tip_joint_0" type="revolute">
    <origin xyz="0.008023428963497281 8.032657206058502e-08 0.08564414083957672"/>
    <parent link="link_3"/>
    <child link="link_4"/>
    <axis xyz="0.0 1.0 0.0"/>
    <limit lower="-0.060000002" upper="0.8503265" effort="1000.0" velocity="2.0"/>
  </joint>
  <link name="link_4">
    <visual>
      <geometry>
        <mesh filename="assets/geom_9.obj"/>
      </geometry>
      <origin xyz="-0.002854451769962907 0.0 0.019342653453350067"/>
    </visual>
    <collision>
      <geometry>
        <mesh filename="assets/geom_9_col0.obj"/>
      </geometry>
      <origin xyz="-0.002854451769962907 0.0 0.019342653453350067"/>
    </collision>
  </link>
  <link name="link_3">
    <visual>
      <geometry>
        <mesh filename="assets/geom_6.obj"/>
      </geometry>
      <origin xyz="0.00446596834808588 0.0 0.04432525485754013"/>
    </visual>
    <collision>
      <geometry>
        <mesh filename="assets/geom_6_col0.obj"/>
      </geometry>
      <origin xyz="0.00446596834808588 0.0 0.04432525485754013"/>
    </collision>
    <visual>
      <geometry>
        <mesh filename="assets/geom_7.obj"/>
      </geometry>
      <origin xyz="-0.007051357068121433 -8.35862010717392e-08 0.009746059775352478"/>
    </visual>
    <collision>
      <geometry>
        <mesh filename="assets/geom_7_col0.obj"/>
      </geometry>
      <origin xyz="-0.007051357068121433 -8.35862010717392e-08 0.009746059775352478"/>
    </collision>
    <visual>
      <geometry>
        <mesh filename="assets/geom_8.obj"/>
      </geometry>
      <origin xyz="-0.006051355507224798 -7.648486644029617e-08 0.05256493389606476"/>
    </visual>
    <collision>
      <geometry>
        <mesh filename="assets/geom_8_col0.obj"/>
      </geometry>
      <origin xyz="-0.006051355507224798 -7.648486644029617e-08 0.05256493389606476"/>
    </collision>
  </link>
  <link name="link_0">
    <visual>
      <geometry>
        <mesh filename="assets/geom_0.obj"/>
      </geometry>
      <origin xyz="0.0 0.0 0.01174366194754839"/>
    </visual>
    <collision>
      <geometry>
        <mesh filename="assets/geom_0_col0.obj"/>
      </geometry>
      <origin xyz="0.0 0.0 0.01174366194754839"/>
    </collision>
    <visual>
      <geometry>
        <mesh filename="assets/geom_1.obj"/>
      </geometry>
      <origin xyz="0.0 4.656612873077393e-10 0.07241559028625488"/>
    </visual>
    <collision>
      <geometry>
        <mesh filename="assets/geom_1_col0.obj"/>
      </geometry>
      <origin xyz="0.0 4.656612873077393e-10 0.07241559028625488"/>
    </collision>
  </link>
</robot>