<?xml version="1.0" ?>
<robot name="hand">
  <link name="world"/>
  <joint name="world_joint" type="fixed">
    <origin xyz="0.0 0.0 0.0"/>
    <parent link="world"/>
    <child link="link_0"/>
  </joint>
  <joint name="right_joint_0" type="prismatic">
    <origin xyz="0.008220330812036991 0.0 0.1262522116303444"/>
    <parent link="link_0"/>
    <child link="link_1"/>
    <axis xyz="1.0 0.0 0.0"/>
    <limit lower="0.0" upper="0.041024603" effort="1000.0" velocity="2.0"/>
  </joint>
  <link name="link_1">
    <visual>
      <geometry>
        <mesh filename="assets/right_finger_0.obj"/>
      </geometry>
      <origin xyz="0.0 0.0 0.0"/>
    </visual>
    <collision>
      <geometry>
        <mesh filename="assets/right_finger_0_col0.obj"/>
      </geometry>
      <origin xyz="0.0 0.0 0.0"/>
    </collision>
  </link>
  <joint name="left_joint_0" type="prismatic">
    <origin xyz="-0.008220330349942628 -5.960464477539063e-08 0.1262522116303444"/>
    <parent link="link_0"/>
    <child link="link_2"/>
    <axis xyz="-1.0 0.0 0.0"/>
    <limit lower="0.0" upper="0.041024603" effort="1000.0" velocity="2.0"/>
  </joint>
  <link name="link_2">
    <visual>
      <geometry>
        <mesh filename="assets/left_finger_0.obj"/>
      </geometry>
      <origin xyz="0.0 0.0 0.0"/>
    </visual>
    <collision>
      <geometry>
        <mesh filename="assets/left_finger_0_col0.obj"/>
      </geometry>
      <origin xyz="0.0 0.0 0.0"/>
    </collision>
  </link>
  <link name="link_0">
    <visual>
      <geometry>
        <mesh filename="assets/base_0.obj"/>
      </geometry>
      <origin xyz="0.0 0.0 0.015792962163686752"/>
    </visual>
    <collision>
      <geometry>
        <mesh filename="assets/base_0_col0.obj"/>
      </geometry>
      <origin xyz="0.0 0.0 0.015792962163686752"/>
    </collision>
    <visual>
      <geometry>
        <mesh filename="assets/base_1.obj"/>
      </geometry>
      <origin xyz="0.0 0.0 0.050338754430413246"/>
    </visual>
    <collision>
      <geometry>
        <mesh filename="assets/base_1_col0.obj"/>
      </geometry>
      <origin xyz="0.0 0.0 0.050338754430413246"/>
    </collision>
  </link>
</robot>