<?xml version="1.0" ?>
<robot name="hand">
  <link name="world"/>
  <joint name="world_joint" type="fixed">
    <origin xyz="0.0 0.0 0.0"/>
    <parent link="world"/>
    <child link="link_0"/>
  </joint>
  <joint name="finger_1_0" type="revolute">
    <origin xyz="0.03992716781795025 0.0 0.03502938221208751"/>
    <parent link="link_0"/>
    <child link="link_1"/>
    <axis xyz="0.0 -1.0 0.0"/>
    <limit lower="0.0" upper="2.151741" effort="1000.0" velocity="2.0"/>
  </joint>
  <joint name="fingertip_1_0" type="revolute">
    <origin xyz="0.03915787115693092 0.0 0.00758181931450963"/>
    <parent link="link_1"/>
    <child link="link_2"/>
    <axis xyz="0.0 -1.0 0.0"/>
    <limit lower="0.0" upper="1.8663043" effort="1000.0" velocity="2.0"/>
  </joint>
  <link name="link_2">
    <visual>
      <geometry>
        <mesh filename="assets/geom_2.obj"/>
      </geometry>
      <origin xyz="0.024106761440634727 0.0 -0.0037909105885773897"/>
    </visual>
    <collision>
      <geometry>
        <mesh filename="assets/geom_2_col0.obj"/>
      </geometry>
      <origin xyz="0.024106761440634727 0.0 -0.0037909105885773897"/>
    </collision>
  </link>
  <link name="link_1">
    <visual>
      <geometry>
        <mesh filename="assets/geom_1.obj"/>
      </geometry>
      <origin xyz="0.01957893557846546 0.0 0.0037909105885773897"/>
    </visual>
    <collision>
      <geometry>
        <mesh filename="assets/geom_1_col0.obj"/>
      </geometry>
      <origin xyz="0.01957893557846546 0.0 0.0037909105885773897"/>
    </collision>
  </link>
  <joint name="finger_2_0" type="revolute">
    <origin xyz="-0.01996358297765255 0.02492850972339511 0.027447559870779514"/>
    <parent link="link_0"/>
    <child link="link_3"/>
    <axis xyz="0.0 1.0 0.0"/>
    <limit lower="0.0" upper="1.8115958" effort="1000.0" velocity="2.0"/>
  </joint>
  <joint name="fingertip_2_0" type="revolute">
    <origin xyz="-0.03915784880518913 1.3131648302078247e-07 0.0037909115198999643"/>
    <parent link="link_3"/>
    <child link="link_4"/>
    <axis xyz="0.0 1.0 0.0"/>
    <limit lower="0.0" upper="1.9792823" effort="1000.0" velocity="2.0"/>
  </joint>
  <link name="link_4">
    <visual>
      <geometry>
        <mesh filename="assets/geom_4.obj"/>
      </geometry>
      <origin xyz="-0.024106761440634727 0.0 -0.0037909105885773897"/>
    </visual>
    <collision>
      <geometry>
        <mesh filename="assets/geom_4_col0.obj"/>
      </geometry>
      <origin xyz="-0.024106761440634727 0.0 -0.0037909105885773897"/>
    </collision>
  </link>
  <link name="link_3">
    <visual>
      <geometry>
        <mesh filename="assets/geom_3.obj"/>
      </geometry>
      <origin xyz="-0.01957893557846546 0.0 0.0"/>
    </visual>
    <collision>
      <geometry>
        <mesh filename="assets/geom_3_col0.obj"/>
      </geometry>
      <origin xyz="-0.01957893557846546 0.0 0.0"/>
    </collision>
  </link>
  <joint name="finger_3_0" type="revolute">
    <origin xyz="-0.01996358297765255 -0.02492850972339511 0.027447559870779514"/>
    <parent link="link_0"/>
    <child link="link_5"/>
    <axis xyz="0.0 1.0 0.0"/>
    <limit lower="0.0" upper="1.8115958" effort="1000.0" velocity="2.0"/>
  </joint>
  <joint name="fingertip_3_0" type="revolute">
    <origin xyz="-0.03915784880518913 1.30385160446167e-07 0.0037909115198999643"/>
    <parent link="link_5"/>
    <child link="link_6"/>
    <axis xyz="0.0 1.0 0.0"/>
    <limit lower="0.0" upper="1.9792823" effort="1000.0" velocity="2.0"/>
  </joint>
  <link name="link_6">
    <visual>
      <geometry>
        <mesh filename="assets/geom_6.obj"/>
      </geometry>
      <origin xyz="-0.024106761440634727 0.0 -0.0037909105885773897"/>
    </visual>
    <collision>
      <geometry>
        <mesh filename="assets/geom_6_col0.obj"/>
      </geometry>
      <origin xyz="-0.024106761440634727 0.0 -0.0037909105885773897"/>
    </collision>
  </link>
  <link name="link_5">
    <visual>
      <geometry>
        <mesh filename="assets/geom_5.obj"/>
      </geometry>
      <origin xyz="-0.01957893557846546 0.0 0.0"/>
    </visual>
    <collision>
      <geometry>
        <mesh filename="assets/geom_5_col0.obj"/>
      </geometry>
      <origin xyz="-0.01957893557846546 0.0 0.0"/>
    </collision>
  </link>
  <link name="link_0">
    <visual>
      <geometry>
        <mesh filename="assets/geom_0.obj"/>
      </geometry>
      <origin xyz="0.0199635848402977 1.862645149230957e-09 0.017514689825475216"/>
    </visual>
    <collision>
      <geometry>
        <mesh filename="assets/geom_0_col0.obj"/>
      </geometry>
      <origin xyz="0.0199635848402977 1.862645149230957e-09 0.017514689825475216"/>
    </collision>
  </link>
</robot>