<?xml version="1.0" ?>
<robot name="hand">
  <link name="world"/>
  <joint name="world_joint" type="fixed">
    <origin xyz="0.0 0.0 0.0"/>
    <parent link="world"/>
    <child link="link_0"/>
  </joint>
  <joint name="finger_1_0" type="revolute">
    <origin xyz="0.04726319946348667 0.0 0.09656606707721949"/>
    <parent link="link_0"/>
    <child link="link_1"/>
    <axis xyz="0.0 -1.0 0.0"/>
    <limit lower="0.0" upper="2.235151" effort="1000.0" velocity="2.0"/>
  </joint>
  <joint name="fingermid_1_0" type="revolute">
    <origin xyz="0.05951881967484951 0.0 0.009539286140352488"/>
    <parent link="link_1"/>
    <child link="link_2"/>
    <axis xyz="0.0 -1.0 0.0"/>
    <limit lower="0.0" upper="1.6078719" effort="1000.0" velocity="2.0"/>
  </joint>
  <joint name="fingertip_1_0" type="revolute">
    <origin xyz="0.049844675697386265 -4.656612873077393e-10 -0.0031797620467841625"/>
    <parent link="link_2"/>
    <child link="link_3"/>
    <axis xyz="0.0 1.0 0.0"/>
    <limit lower="0.0" upper="0.8868628" effort="1000.0" velocity="2.0"/>
  </joint>
  <link name="link_3">
    <visual>
      <geometry>
        <mesh filename="assets/geom_3.obj"/>
      </geometry>
      <origin xyz="0.009856021963059902 0.0 0.0"/>
    </visual>
    <collision>
      <geometry>
        <mesh filename="assets/geom_3_col0.obj"/>
      </geometry>
      <origin xyz="0.009856021963059902 0.0 0.0"/>
    </collision>
  </link>
  <link name="link_2">
    <visual>
      <geometry>
        <mesh filename="assets/geom_2.obj"/>
      </geometry>
      <origin xyz="0.026234041899442673 0.0 -0.0031797620467841625"/>
    </visual>
    <collision>
      <geometry>
        <mesh filename="assets/geom_2_col0.obj"/>
      </geometry>
      <origin xyz="0.026234041899442673 0.0 -0.0031797620467841625"/>
    </collision>
  </link>
  <link name="link_1">
    <visual>
      <geometry>
        <mesh filename="assets/geom_1.obj"/>
      </geometry>
      <origin xyz="0.03107110969722271 0.0 0.006359524093568325"/>
    </visual>
    <collision>
      <geometry>
        <mesh filename="assets/geom_1_col0.obj"/>
      </geometry>
      <origin xyz="0.03107110969722271 0.0 0.006359524093568325"/>
    </collision>
  </link>
  <joint name="finger_2_0" type="revolute">
    <origin xyz="-0.04767759330570698 0.034555304795503616 0.09338629990816116"/>
    <parent link="link_0"/>
    <child link="link_4"/>
    <axis xyz="0.0 1.0 0.0"/>
    <limit lower="0.0" upper="2.235151" effort="1000.0" velocity="2.0"/>
  </joint>
  <joint name="fingermid_2_0" type="revolute">
    <origin xyz="-0.05951881594955921 0.0 0.0031797620467841625"/>
    <parent link="link_4"/>
    <child link="link_5"/>
    <axis xyz="0.0 1.0 0.0"/>
    <limit lower="0.0" upper="1.6078719" effort="1000.0" velocity="2.0"/>
  </joint>
  <joint name="fingertip_2_0" type="revolute">
    <origin xyz="-0.049844671972095966 5.21540641784668e-08 -0.0031797620467841625"/>
    <parent link="link_5"/>
    <child link="link_6"/>
    <axis xyz="0.0 -1.0 0.0"/>
    <limit lower="0.0" upper="0.8868628" effort="1000.0" velocity="2.0"/>
  </joint>
  <link name="link_6">
    <visual>
      <geometry>
        <mesh filename="assets/geom_6.obj"/>
      </geometry>
      <origin xyz="-0.009856021963059902 0.0 0.0"/>
    </visual>
    <collision>
      <geometry>
        <mesh filename="assets/geom_6_col0.obj"/>
      </geometry>
      <origin xyz="-0.009856021963059902 0.0 0.0"/>
    </collision>
  </link>
  <link name="link_5">
    <visual>
      <geometry>
        <mesh filename="assets/geom_5.obj"/>
      </geometry>
      <origin xyz="-0.026234041899442673 0.0 -0.0031797620467841625"/>
    </visual>
    <collision>
      <geometry>
        <mesh filename="assets/geom_5_col0.obj"/>
      </geometry>
      <origin xyz="-0.026234041899442673 0.0 -0.0031797620467841625"/>
    </collision>
  </link>
  <link name="link_4">
    <visual>
      <geometry>
        <mesh filename="assets/geom_4.obj"/>
      </geometry>
      <origin xyz="-0.03107110969722271 0.0 0.0"/>
    </visual>
    <collision>
      <geometry>
        <mesh filename="assets/geom_4_col0.obj"/>
      </geometry>
      <origin xyz="-0.03107110969722271 0.0 0.0"/>
    </collision>
  </link>
  <joint name="finger_3_0" type="revolute">
    <origin xyz="-0.04767759330570698 -0.034555304795503616 0.09338629990816116"/>
    <parent link="link_0"/>
    <child link="link_7"/>
    <axis xyz="0.0 1.0 0.0"/>
    <limit lower="0.0" upper="2.235151" effort="1000.0" velocity="2.0"/>
  </joint>
  <joint name="fingermid_3_0" type="revolute">
    <origin xyz="-0.05951881594955921 0.0 0.0031797620467841625"/>
    <parent link="link_7"/>
    <child link="link_8"/>
    <axis xyz="0.0 1.0 0.0"/>
    <limit lower="0.0" upper="1.6078719" effort="1000.0" velocity="2.0"/>
  </joint>
  <joint name="fingertip_3_0" type="revolute">
    <origin xyz="-0.049844671972095966 5.3085386753082275e-08 -0.0031797620467841625"/>
    <parent link="link_8"/>
    <child link="link_9"/>
    <axis xyz="0.0 -1.0 0.0"/>
    <limit lower="0.0" upper="0.8868628" effort="1000.0" velocity="2.0"/>
  </joint>
  <link name="link_9">
    <visual>
      <geometry>
        <mesh filename="assets/geom_9.obj"/>
      </geometry>
      <origin xyz="-0.009856021963059902 0.0 0.0"/>
    </visual>
    <collision>
      <geometry>
        <mesh filename="assets/geom_9_col0.obj"/>
      </geometry>
      <origin xyz="-0.009856021963059902 0.0 0.0"/>
    </collision>
  </link>
  <link name="link_8">
    <visual>
      <geometry>
        <mesh filename="assets/geom_8.obj"/>
      </geometry>
      <origin xyz="-0.026234041899442673 0.0 -0.0031797620467841625"/>
    </visual>
    <collision>
      <geometry>
        <mesh filename="assets/geom_8_col0.obj"/>
      </geometry>
      <origin xyz="-0.026234041899442673 0.0 -0.0031797620467841625"/>
    </collision>
  </link>
  <link name="link_7">
    <visual>
      <geometry>
        <mesh filename="assets/geom_7.obj"/>
      </geometry>
      <origin xyz="-0.03107110969722271 0.0 0.0"/>
    </visual>
    <collision>
      <geometry>
        <mesh filename="assets/geom_7_col0.obj"/>
      </geometry>
      <origin xyz="-0.03107110969722271 0.0 0.0"/>
    </collision>
  </link>
  <link name="link_0">
    <visual>
      <geometry>
        <mesh filename="assets/geom_0.obj"/>
      </geometry>
      <origin xyz="0.0 0.0 0.04987291060388088"/>
    </visual>
    <collision>
      <geometry>
        <mesh filename="assets/geom_0_col0.obj"/>
      </geometry>
      <origin xyz="0.0 0.0 0.04987291060388088"/>
    </collision>
  </link>
</robot>